<robot name="onshape">
    <link name="chassi">
        <visual>
            <origin xyz="0 0 0" rpy="0 -0 0" />
            <geometry>
                <mesh filename="package:///chassi.stl"/>
            </geometry>
            <material name="chassi_material">
                <color rgba="0.97254901960784312376 0.52941176470588235947 0.0039215686274509803377 1.0"/>
            </material>
        </visual>
        <collision>
            <origin xyz="0 0 0" rpy="0 -0 0" />
            <geometry>
                <mesh filename="package:///chassi.stl"/>
            </geometry>
        </collision>
        <inertial>
            <origin xyz="-1.3888683065720882407e-07 0.0082819323677575940046 0.020809805390406065778" rpy="0 0 0"/>
            <mass value="0.20194158243422738463" />
            <inertia ixx="0.00033777424928967781726" ixy="2.943300128208976461e-10"  ixz="2.9214317318753557249e-10" iyy="0.00020664116040940486412" iyz="9.6138312460583150631e-06" izz="0.00042508835219934575783" />
        </inertial>
    </link>

    <link name="motrice_wheel_left">
        <visual>
            <origin xyz="0 0 0" rpy="3.141592653589793116 -0 0" />
            <geometry>
                <mesh filename="package:///motrice_wheel_left.stl"/>
            </geometry>
            <material name="motrice_wheel_left_material">
                <color rgba="0.61568627450980395466 0.81176470588235294379 0.92941176470588238168 1.0"/>
            </material>
        </visual>
        <collision>
            <origin xyz="0 0 0" rpy="3.141592653589793116 -0 0" />
            <geometry>
                <cylinder radius="0.03375" length="0.022"/>
            </geometry>
        </collision>
        <inertial>
            <origin xyz="-5.9111855801482170637e-18 -7.479483172012212741e-19 3.1373176309269954017e-18" rpy="0 0 0"/>
            <mass value="0.11139468208003587557" />
            <inertia ixx="3.5498465877564320951e-05" ixy="0"  ixz="1.5135375518184446714e-10" iyy="3.5498465877564327727e-05" iyz="0" izz="6.242312441208364409e-05" />
        </inertial>
    </link>

    <joint name="wheel_left" type="continuous">
        <origin xyz="-0.056000205455824500489 0.03000000000000037359 0.013750000000000012212" rpy="-3.141592653589793116 1.570796326794896558 0" />
        <parent link="chassi" />
        <child link="motrice_wheel_left" />
        <axis xyz="0 0 1"/>
        <limit effort="1" velocity="20" />
        <joint_properties friction="0.0"/>
    </joint>

    <link name="support_free_wheel">
        <visual>
            <origin xyz="0 0 -0.0012499999999999993755" rpy="3.141592653589793116 -0 0" />
            <geometry>
                <mesh filename="package:///support_free_wheel.stl"/>
            </geometry>
            <material name="support_free_wheel_material">
                <color rgba="0.2313725490196078538 0.38039215686274507888 0.7058823529411765163 1.0"/>
            </material>
        </visual>
        <collision>
            <origin xyz="0 0 -0.0012499999999999993755" rpy="3.141592653589793116 -0 0" />
            <geometry>
                <mesh filename="package:///support_free_wheel.stl"/>
            </geometry>
        </collision>
        <inertial>
            <origin xyz="3.2959109110925198729e-19 0.0015024937235641716137 0.0052129311092733807836" rpy="0 0 0"/>
            <mass value="0.031455321354957842261" />
            <inertia ixx="3.5046071251828348014e-06" ixy="0"  ixz="0" iyy="4.1903989692231801659e-06" iyz="-5.34965553032055797e-07" izz="5.3987283987018527394e-06" />
        </inertial>
    </link>

    <link name="free_wheel">
        <visual>
            <origin xyz="0 0 0" rpy="3.141592653589793116 -0 0" />
            <geometry>
                <mesh filename="package:///free_wheel.stl"/>
            </geometry>
            <material name="free_wheel_material">
                <color rgba="0.64705882352941179736 0.64705882352941179736 0.64705882352941179736 1.0"/>
            </material>
        </visual>
        <collision>
            <origin xyz="0 0 0" rpy="3.141592653589793116 -0 0" />
            <geometry>
                <cylinder radius="0.012" length="0.015"/>
            </geometry>
        </collision>
        <inertial>
            <origin xyz="-2.4333491813328602692e-19 -2.0943948194202893403e-20 1.0306134484624055856e-18" rpy="0 0 0"/>
            <mass value="0.0094194304211783728975" />
            <inertia ixx="5.1050034385208465051e-07" ixy="-2.5658654044881783198e-90"  ixz="-6.7267820170706031254e-12" iyy="5.1050034385208465051e-07" iyz="6.4972846143077667903e-86" izz="6.8083592430328584928e-07" />
        </inertial>
    </link>

    <joint name="freewheel" type="revolute">
        <origin xyz="-3.4694469519536141888e-18 0.01196700208589383807 0.018850000000000016048" rpy="-2.7369110631344083416e-48 1.570796326794896558 0" />
        <parent link="support_free_wheel" />
        <child link="free_wheel" />
        <axis xyz="0 0 1"/>
        <limit effort="1" velocity="20" />
        <joint_properties friction="0.0"/>
    </joint>

    <joint name="support_continuous" type="continuous">
        <origin xyz="-2.0710723963937582859e-07 -0.084424061722245452577 0.01074999999999993669" rpy="3.141592653589793116 -0 3.141592653589793116" />
        <parent link="chassi" />
        <child link="support_free_wheel" />
        <axis xyz="0 0 1"/>
        <limit effort="1" velocity="20" />
        <joint_properties friction="0.0"/>
    </joint>

    <link name="motrice_wheel_right">
        <visual>
            <origin xyz="0 0 0" rpy="3.141592653589793116 -0 0" />
            <geometry>
                <mesh filename="package:///motrice_wheel_right.stl"/>
            </geometry>
            <material name="motrice_wheel_right_material">
                <color rgba="0.61568627450980395466 0.81176470588235294379 0.92941176470588238168 1.0"/>
            </material>
        </visual>
        <collision>
            <origin xyz="0 0 0" rpy="3.141592653589793116 -0 0" />
            <geometry>
                <cylinder radius="0.03375" length="0.022"/>
            </geometry>
        </collision>
        <inertial>
            <origin xyz="-5.9111855801482170637e-18 -7.479483172012212741e-19 3.1373176309269954017e-18" rpy="0 0 0"/>
            <mass value="0.11139468208003587557" />
            <inertia ixx="3.5498465877564320951e-05" ixy="0"  ixz="1.5135375518184446714e-10" iyy="3.5498465877564327727e-05" iyz="0" izz="6.242312441208364409e-05" />
        </inertial>
    </link>

    <joint name="wheel_right" type="continuous">
        <origin xyz="0.055999788521511037476 0.03000000000000037359 0.013750000000000012212" rpy="-0 1.570796326794896558 0" />
        <parent link="chassi" />
        <child link="motrice_wheel_right" />
        <axis xyz="0 0 1"/>
        <limit effort="1" velocity="20" />
        <joint_properties friction="0.0"/>
    </joint>


</robot>
